Workbook

Sheet EMA
A3: Movimientos por Asegurado de EMA
A5: NSS | B5: Nombre | C5: Origen del Movimiento | D5: Tipo del Movimiento | E5: Fecha del Movimiento | F5: Días | G5: Salario Diario | H5: Cuota Fija | I5: Excedente Patronal | J5: Excedente Obrero | K5: Prestaciones en Dinero Patronal | L5: Prestaciones en Dinero Obrero | M5: Gastos Médicos y Pensionados Patronal | N5: Gastos Médicos y Pensionados Obrero | O5: Riesgos de Trabajo | P5: Invalidez y Vida Patronal | Q5: Invalidez y Vida Obrero | R5: Guarderías y Prestaciones Sociales | S5: Total
A6: 16129527558 | B6: AGUILAR ARRIAGA BENJAMIN | C6: 4 | D6: 9 | E6: - | F6: 28 | G6: 935.04 | H6: 670.07 | I6: 179.6 | J6: 65.31 | K6: 183.27 | L6: 65.45 | M6: 274.9 | N6: 98.18 | O6: 142.66 | P6: 458.17 | Q6: 163.63 | R6: 261.81 | S6: 2563.05
A7: 17169570706 | B7: AGUILAR CARBAJAL SANTOS | C7: 4 | D7: 9 | E7: - | F7: 28 | G7: 399.93 | H7: 670.07 | I7: 14.78 | J7: 5.38 | K7: 78.39 | L7: 28 | M7: 117.58 | N7: 41.99 | O7: 61.02 | P7: 195.97 | Q7: 69.99 | R7: 111.98 | S7: 1395.15
A8: 16055900472 | B8: ALTAMIRANO HERNANDEZ SERGIO VICTOR | C8: 4 | D8: 9 | E8: - | F8: 28 | G8: 1005.61 | H8: 670.07 | I8: 201.33 | J8: 73.21 | K8: 197.1 | L8: 70.39 | M8: 295.65 | N8: 105.59 | O8: 153.43 | P8: 492.75 | Q8: 175.98 | R8: 281.57 | S8: 2717.07
A9: 10199887299 | B9: ANTONIO ROQUE GIOVANNI | C9: 4 | D9: 9 | E9: - | F9: 28 | G9: 525.63 | H9: 670.07 | I9: 53.5 | J9: 19.45 | K9: 103.02 | L9: 36.79 | M9: 154.54 | N9: 55.19 | O9: 80.2 | P9: 257.56 | Q9: 91.99 | R9: 147.18 | S9: 1669.49
A10: 17159479306 | B10: ARIAS ANTONIO RUTILO | C10: 4 | D10: 9 | E10: - | F10: 28 | G10: 357.16 | H10: 670.07 | I10: 1.61 | J10: 0.59 | K10: 70 | L10: 25 | M10: 105.01 | N10: 37.5 | O10: 54.49 | P10: 175.01 | Q10: 62.5 | R10: 100 | S10: 1301.78
A11: 16916950013 | B11: ARZATE BARCENAS LORENZO | C11: 4 | D11: 9 | E11: - | F11: 28 | G11: 736.15 | H11: 670.07 | I11: 118.34 | J11: 43.03 | K11: 144.29 | L11: 51.53 | M11: 216.43 | N11: 77.3 | O11: 112.32 | P11: 360.71 | Q11: 128.83 | R11: 206.12 | S11: 2128.97
A12: 16058300399 | B12: AVILA CASAS JAIME | C12: 4 | D12: 9 | E12: - | F12: 28 | G12: 490.17 | H12: 670.07 | I12: 42.58 | J12: 15.48 | K12: 96.07 | L12: 34.31 | M12: 144.11 | N12: 51.47 | O12: 74.79 | P12: 240.18 | Q12: 85.78 | R12: 137.25 | S12: 1592.09
A13: 16169722564 | B13: AVILA GARCIA ARACELI | C13: 4 | D13: 9 | E13: - | F13: 28 | G13: 1201.12 | H13: 670.07 | I13: 261.55 | J13: 95.11 | K13: 235.42 | L13: 84.08 | M13: 353.13 | N13: 126.12 | O13: 183.26 | P13: 588.55 | Q13: 210.2 | R13: 336.31 | S13: 3143.8
A14: 16089120402 | B14: AVILA MIRALRIO CLEOFAS | C14: 4 | D14: 9 | E14: - | F14: 28 | G14: 618.53 | H14: 670.07 | I14: 82.11 | J14: 29.86 | K14: 121.23 | L14: 43.3 | M14: 181.85 | N14: 64.95 | O14: 94.37 | P14: 303.08 | Q14: 108.24 | R14: 173.19 | S14: 1872.25
A15: 10199987412 | B15: AVILA SANCHEZ FELIPE | C15: 1 | D15: 9 | E15: - | F15: 28 | G15: 330.57 | H15: 670.07 | I15: 0 | J15: 0 | K15: 64.79 | L15: 23.14 | M15: 97.19 | N15: 34.71 | O15: 50.44 | P15: 161.98 | Q15: 57.85 | R15: 92.56 | S15: 1252.73
A16: 04169357409 | B16: BARTOLO DE LA CRUZ TOMAS | C16: 4 | D16: 9 | E16: - | F16: 28 | G16: 552.76 | H16: 670.07 | I16: 61.86 | J16: 22.49 | K16: 108.34 | L16: 38.69 | M16: 162.51 | N16: 58.04 | O16: 84.34 | P16: 270.85 | Q16: 96.73 | R16: 154.77 | S16: 1728.69
A17: 16139548891 | B17: CABALLERO HERNANDEZ GUADALUPE | C17: 4 | D17: 9 | E17: - | F17: 28 | G17: 1471.3 | H17: 670.07 | I17: 344.77 | J17: 125.37 | K17: 288.37 | L17: 102.99 | M17: 432.56 | N17: 154.49 | O17: 224.48 | P17: 720.94 | Q17: 257.48 | R17: 411.96 | S17: 3733.48
... A214: 10179770929 | B214: ZEPEDA CORTES RODRIGO | C214: 4 | D214: 9 | E214: - | F214: 28 | G214: 679.8 | H214: 670.07 | I214: 100.98 | J214: 36.72 | K214: 133.24 | L214: 47.59 | M214: 199.86 | N214: 71.38 | O214: 103.72 | P214: 333.1 | Q214: 118.97 | R214: 190.34 | S214: 2005.97

Sheet EBA
A3: Movimientos por Asegurado de EBA
A5: NSS | B5: Nombre | C5: Origen del Movimiento | D5: Tipo del Movimiento | E5: Fecha del Movimiento | F5: Días | G5: Salario Diario | H5: Retiro | I5: Cesantía en Edad Avanzada y Vejez Patronal | J5: Cesantía en Edad Avanzada y Vejez Obrero | K5: Subtotal RCV | L5: Aportación Patronal | M5: Tipo de Descuento | N5: Valor de Descuento | O5: Número de Crédito | P5: Amortización | Q5: Subtotal Infonavit | R5: Total
A6: 16129527558 | B6: AGUILAR ARRIAGA BENJAMIN | C6: 4 | D6: 7 | E6: 1/ENE/2026 | F6: 59 | G6: 935.04 | H6: 1103.35 | I6: 4144.73 | J6: 620.63 | K6: 5868.71 | L6: 2758.37 | M6: - | N6: - | O6: - | P6: 0 | Q6: 2758.37 | R6: 8627.08
A7: 17169570706 | B7: AGUILAR CARBAJAL SANTOS | C7: 4 | D7: 7 | E7: 1/ENE/2026 | F7: 59 | G7: 399.93 | H7: 471.92 | I7: 1532.18 | J7: 265.45 | K7: 2269.55 | L7: 1179.79 | M7: - | N7: - | O7: - | P7: 0 | Q7: 1179.79 | R7: 3449.34
A8: 16055900472 | B8: ALTAMIRANO HERNANDEZ SERGIO VICTOR | C8: 4 | D8: 7 | E8: 1/ENE/2026 | F8: 59 | G8: 1005.61 | H8: 1186.62 | I8: 4457.54 | J8: 667.47 | K8: 6311.63 | L8: 2966.55 | M8: - | N8: - | O8: - | P8: 0 | Q8: 2966.55 | R8: 9278.18
A9: 10199887299 | B9: ANTONIO ROQUE GIOVANNI | C9: 4 | D9: 7 | E9: 1/ENE/2026 | F9: 59 | G9: 525.63 | H9: 620.24 | I9: 2329.95 | J9: 348.89 | K9: 3299.08 | L9: 1550.61 | M9: - | N9: - | O9: - | P9: 0 | Q9: 1550.61 | R9: 4849.69
A10: 17159479306 | B10: ARIAS ANTONIO RUTILO | C10: 4 | D10: 7 | E10: 1/ENE/2026 | F10: 59 | G10: 357.16 | H10: 421.45 | I10: 1340.42 | J10: 237.06 | K10: 1998.93 | L10: 1053.62 | M10: - | N10: - | O10: - | P10: 0 | Q10: 1053.62 | R10: 3052.55
A11: 16916950013 | B11: ARZATE BARCENAS LORENZO | C11: 4 | D11: 7 | E11: 1/ENE/2026 | F11: 59 | G11: 736.15 | H11: 868.66 | I11: 3263.11 | J11: 488.62 | K11: 4620.39 | L11: 2171.64 | M11: - | N11: - | O11: - | P11: 0 | Q11: 2171.64 | R11: 6792.03
A12: 16058300399 | B12: AVILA CASAS JAIME | C12: 4 | D12: 7 | E12: 1/ENE/2026 | F12: 59 | G12: 490.17 | H12: 578.4 | I12: 2172.76 | J12: 325.35 | K12: 3076.51 | L12: 1446 | M12: - | N12: - | O12: - | P12: 0 | Q12: 1446 | R12: 4522.51
A13: 16169722564 | B13: AVILA GARCIA ARACELI | C13: 4 | D13: 7 | E13: 1/ENE/2026 | F13: 59 | G13: 1201.12 | H13: 1417.32 | I13: 5324.16 | J13: 797.24 | K13: 7538.72 | L13: 3543.3 | M13: - | N13: - | O13: - | P13: 0 | Q13: 3543.3 | R13: 11082.02
A14: 16089120402 | B14: AVILA MIRALRIO CLEOFAS | C14: 4 | D14: 7 | E14: 1/ENE/2026 | F14: 59 | G14: 618.53 | H14: 729.87 | I14: 2741.73 | J14: 410.55 | K14: 3882.15 | L14: 1824.66 | M14: - | N14: - | O14: - | P14: 0 | Q14: 1824.66 | R14: 5706.81
A15: 10199987412 | B15: AVILA SANCHEZ FELIPE | C15: 1 | D15: 7 | E15: 1/ENE/2026 | F15: 59 | G15: 330.57 | H15: 390.07 | I15: 1175.28 | J15: 219.42 | K15: 1784.77 | L15: 975.18 | M15: - | N15: - | O15: - | P15: 0 | Q15: 975.18 | R15: 2759.95
A16: 04169357409 | B16: BARTOLO DE LA CRUZ TOMAS | C16: 4 | D16: 7 | E16: 1/ENE/2026 | F16: 59 | G16: 552.76 | H16: 652.26 | I16: 2450.2 | J16: 366.89 | K16: 3469.35 | L16: 1630.64 | M16: - | N16: - | O16: - | P16: 0 | Q16: 1630.64 | R16: 5099.99
A17: 16139548891 | B17: CABALLERO HERNANDEZ GUADALUPE | C17: 4 | D17: 7 | E17: 1/ENE/2026 | F17: 59 | G17: 1471.3 | H17: 1736.13 | I17: 6521.79 | J17: 976.58 | K17: 9234.5 | L17: 4340.34 | M17: - | N17: - | O17: - | P17: 0 | Q17: 4340.34 | R17: 13574.84
... A225: 10179770929 | B225: ZEPEDA CORTES RODRIGO | C225: 4 | D225: 7 | E225: 1/ENE/2026 | F225: 59 | G225: 679.8 | H225: 802.16 | I225: 3013.32 | J225: 451.22 | K225: 4266.7 | L225: 2005.41 | M225: - | N225: - | O225: - | P225: 0 | Q225: 2005.41 | R225: 6272.11

Sheet FEBRERO
AF2: PRORRATEO IMSS BIMESTRAL JUNIO 2025 POR ÁREA
A3: NSS | B3: Nombre | C3: Departamento | D3: Origen del Movimiento | E3: Tipo del Movimiento | F3: Fecha del Movimiento | G3: Días | H3: Salario Diario | I3: Cuota Fija | J3: Excedente Patronal | K3: Excedente Obrero | L3: Prestaciones en Dinero Patronal | M3: Prestaciones en Dinero Obrero | N3: Gastos Médicos y Pensionados Patronal | O3: Gastos Médicos y Pensionados Obrero | P3: Riesgos de Trabajo | Q3: Invalidez y Vida Patronal | R3: Invalidez y Vida Obrero | S3: Guarderías y Prestaciones Sociales | T3: Cesantía en Edad Avanzada y Vejez Patronal | U3: Cesantía en Edad Avanzada y Vejez Obrero | V3: Retiro | W3: Aportación Patronal | X3: Tipo de Descuento | Y3: Valor de Descuento | Z3: Número de Crédito | AA3: Amortización | AB3: Total | AC3: Subtotal RCV | AD3: Subtotal Infonavit
B4: =+C5 -> 0 | AF4: ADMINISTRACIÓN | AI4: CASCO II | AL4: =+B28 -> 0 | AO4: =+B55 -> 0 | AR4: =+B81 -> 0 | AU4: =+B97 -> 0 | AX4: =+B138 -> 0 | BA4: =+B203 -> 0 | BD4: =+B222 -> 0 | BG4: =+B232 -> 0
AF5: INFONAVIT | AG5: =+W17+AA17 -> 0 | AI5: INFONAVIT | AJ5: =+W26+AA26 -> 0 | AL5: INFONAVIT | AM5: =+W53+AA53 -> 0 | AO5: INFONAVIT | AP5: =+W79+AA79 -> 0 | AR5: INFONAVIT | AS5: =+W95+AA95 -> 0 | AU5: INFONAVIT | AV5: =+W136+AA136 -> 0 | AX5: INFONAVIT | AY5: =+W201+AA201 -> 0 | BA5: INFONAVIT | BB5: =+W220+AA220 -> 0 | BD5: INFONAVIT | BE5: =+W230+AA230 -> 0 | BG5: INFONAVIT | BH5: =+W284+AA284 -> 0
AF6: SAR | AG6: =+V17 -> 0 | AI6: SAR | AJ6: =+V26 -> 0 | AL6: SAR | AM6: =+V53 -> 0 | AO6: SAR | AP6: =+V79 -> 0 | AR6: SAR | AS6: =+V95 -> 0 | AU6: SAR | AV6: =+V136 -> 0 | AX6: SAR | AY6: =+V201 -> 0 | BA6: SAR | BB6: =+V220 -> 0 | BD6: SAR | BE6: =+V230 -> 0 | BG6: SAR | BH6: =+V284 -> 0
AF7: CESANTIA PATRONAL | AG7: =+T17 -> 0 | AI7: CESANTIA PATRONAL | AJ7: =+T26 -> 0 | AL7: CESANTIA PATRONAL | AM7: =+T53 -> 0 | AO7: CESANTIA PATRONAL | AP7: =+T79 -> 0 | AR7: CESANTIA PATRONAL | AS7: =+T95 -> 0 | AU7: CESANTIA PATRONAL | AV7: =+T136 -> 0 | AX7: CESANTIA PATRONAL | AY7: =+T201 -> 0 | BA7: CESANTIA PATRONAL | BB7: =+T220 -> 0 | BD7: CESANTIA PATRONAL | BE7: =+T230 -> 0 | BG7: CESANTIA PATRONAL | BH7: =+T284 -> 0
AF8: CESANTIA OBRERO | AG8: =+U17 -> 0 | AI8: CESANTIA OBRERO | AJ8: =+U26 -> 0 | AL8: CESANTIA OBRERO | AM8: =+U53 -> 0 | AO8: CESANTIA OBRERO | AP8: =+U79 -> 0 | AR8: CESANTIA OBRERO | AS8: =+U95 -> 0 | AU8: CESANTIA OBRERO | AV8: =+U136 -> 0 | AX8: CESANTIA OBRERO | AY8: =+U201 -> 0 | BA8: CESANTIA OBRERO | BB8: =+U220 -> 0 | BD8: CESANTIA OBRERO | BE8: =+U230 -> 0 | BG8: CESANTIA OBRERO | BH8: =+U284 -> 0
AF9: IMSS PATRONAL | AG9: =+I17+J17+L17+N17+P17+Q17+S17 -> 0 | AI9: IMSS PATRONAL | AJ9: =+I26+J26+L26+N26+P26+Q26+S26 -> 0 | AL9: IMSS PATRONAL | AM9: =+I53+J53+L53+N53+P53+Q53+S53-4216.64 -> -4216.64 | AO9: IMSS PATRONAL | AP9: =+I79+J79+L79+N79+P79+Q79+S79 -> 0 | AR9: IMSS PATRONAL | AS9: =+I95+J95+L95+N95+P95+Q95+S95 -> 0 | AU9: IMSS PATRONAL | AV9: =+I136+J136+L136+N136+P136+Q136+S136 -> 0 | AX9: IMSS PATRONAL | AY9: =+I201+J201+L201+N201+P201+Q201+S201 -> 0 | BA9: IMSS PATRONAL | BB9: =+I220+J220+L220+N220+P220+Q220+S220 -> 0 | BD9: IMSS PATRONAL | BE9: =+I230+J230+L230+N230+P230+Q230+S230 -> 0 | BG9: IMSS PATRONAL | BH9: =+I284+J284+L284+N284+P284+Q284+S284 -> 0
AF10: IMSS OBRERO | AG10: =+K17+M17+O17+R17 -> 0 | AI10: IMSS OBRERO | AJ10: =+K26+M26+O26+R26 -> 0 | AL10: IMSS OBRERO | AM10: =+K53+M53+O53+R53 -> 0 | AO10: IMSS OBRERO | AP10: =+K79+M79+O79+R79 -> 0 | AR10: IMSS OBRERO | AS10: =+K95+M95+O95+R95 -> 0 | AU10: IMSS OBRERO | AV10: =+K136+M136+O136+R136 -> 0 | AX10: IMSS OBRERO | AY10: =+K201+M201+O201+R201 -> 0 | BA10: IMSS OBRERO | BB10: =+K220+M220+O220+R220 -> 0 | BD10: IMSS OBRERO | BE10: =+K230+M230+O230+R230 -> 0 | BG10: IMSS OBRERO | BH10: =+K284+M284+O284+R284 -> 0 | BI10: 1473130.9 | BJ10: =+BI11-BI10 -> -1477347.6
AG11: =SUM(AG5:AG10) -> 0 | AJ11: =SUM(AJ5:AJ10) -> 0 | AM11: =SUM(AM5:AM10) -> -4216.64 | AP11: =SUM(AP5:AP10) -> 0 | AS11: =SUM(AS5:AS10) -> 0 | AV11: =SUM(AV5:AV10) -> 0 | AY11: =SUM(AY5:AY10) -> 0 | BB11: =SUM(BB5:BB10) -> 0 | BE11: =SUM(BE5:BE10) -> 0 | BH11: =SUM(BH5:BH10) -> 0 | BI11: =+AG11+AJ11+AM11+AP11+AS11+AV11+AY11+BB11+BE11+BH11 -> -4216.64
AF13: imss | AG13: =+AG9+AG10+AJ9+AJ10+AM9+AM10+AS9+AS10+AV9+AV10+AY9+AY10+BB9+BB10+BH9+BH10 -> -4216.64 | AJ13: =+AJ9+AJ10 -> 0 | AM13: =+AM9+AM10-4216.64 -> -8433.28 | AP13: =+AP9+AP10 -> 0 | AS13: =+AS9+AS10 -> 0 | AV13: =+AV9+AV10 -> 0 | AY13: =AY9+AY10 -> 0 | BB13: =+BB9+BB10 -> 0 | BE13: =+BE9+BE10 -> 0 | BH13: =+BH9+BH10 -> 0
AF14: =+AG11+AJ11+AM11+AP11+AS11+AV11+AY11+BB11+BH11-AF16+BE11 -> 0 | AG14: DIFERENCIA DE MÁS EN SUA
AF16: =+BI11 -> -4216.64 | AG16: SUA
I17: =SUM(I5:I16) -> 0 | J17: =SUM(J5:J16) -> 0 | K17: =SUM(K5:K16) -> 0 | L17: =SUM(L5:L16) -> 0 | M17: =SUM(M5:M16) -> 0 | N17: =SUM(N5:N16) -> 0 | O17: =SUM(O5:O16) -> 0 | P17: =SUM(P5:P16) -> 0 | ... AD17: =SUM(AD5:AD16) -> 0 | AF17: 1477347.6 | AG17: IDSE
AF18: =+AF16-AF17 -> -1481564.2 | AG18: DIFERENCIA
B19: =+C20 -> 0 | AF19: IMSS + CESANTIA OBRERO | AI19: =+AF21+AI21+AL21+AO21+AR21+AU21+AX21+BA21+BD21+BG21 -> 0
AF20: =+AF4 -> ADMINISTRACIÓN | AI20: =+AI4 -> CASCO II | AL20: =+AL4 -> 0 | AO20: =+AO4 -> 0 | AR20: =+AR4 -> 0 | AU20: =+AU4 -> 0 | AX20: =+AX4 -> 0 | BA20: =+BA4 -> 0 | BD20: =+BD4 -> 0 | BG20: =+BG4 -> 0
AF21: =+AG8+AG10 -> 0 | AI21: =+AJ8+AJ10 -> 0 | AL21: =+AM8+AM10 -> 0 | AO21: =+AP8+AP10 -> 0 | AR21: =+AS8+AS10 -> 0 | AU21: =+AV8+AV10 -> 0 | AX21: =+AY8+AY10 -> 0 | BA21: =+BB8+BB10 -> 0 | BD21: =+BE8+BE10 -> 0 | BG21: =+BH8+BH10 -> 0
AF22: =+K23+M23+O23+R23+U23 -> 0 | AI22: =+K38+M38+O38+R38+U38 -> 0 | AL22: =+K68+M68+O68+R68+U68 -> 0 | AO22: =+K105+M105+O105+R105+U105 -> 0 | AR22: =+K117+M117+O117+R117+U117 -> 0 | AU22: =+K187+M187+O187+R187+U187 -> 0 | AX22: =+K277+M277+O277+R277+U277 -> 0 | BA22: =+K311+M311+O311+R311+U311 -> 0 | BD22: =+K322+M322+O322+R322+U322 -> 0 | BG22: =+K380+M380+O380+R380+U380 -> 0
AF23: =+AF21-AF22 -> 0 | AI23: =+AI21-AI22 -> 0 | AL23: =+AL21-AL22 -> 0 | AO23: =+AO21-AO22 -> 0 | AR23: =+AR21-AR22 -> 0 | AU23: =+AU21-AU22 -> 0 | AX23: =+AX21-AX22 -> 0 | BA23: =+BA21-BA22 -> 0 | BD23: =+BD21-BD22 -> 0 | BG23: =+BG21-BG22 -> 0
I26: =SUM(I20:I25) -> 0 | J26: =SUM(J20:J25) -> 0 | K26: =SUM(K20:K25) -> 0 | L26: =SUM(L20:L25) -> 0 | M26: =SUM(M20:M25) -> 0 | N26: =SUM(N20:N25) -> 0 | O26: =SUM(O20:O25) -> 0 | P26: =SUM(P20:P25) -> 0 | ... AD26: =SUM(AD20:AD25) -> 0 | AF26: RESUMEN POR DEPARTAMENTOS
AF27: ADMINISTRACIÓN | AI27: CASCO II + OPERACIÓN | AL27: CENTRO MEDICO EQUINO | AO27: CORRALES | AR27: FORESTAL + JARDINES | BA27: PRODUCCIÓN | BD27: REPRODUCCIÓN | BG27: TRAINING
B28: =+C29 -> 0 | AF28: INFONAVIT | AG28: =+AG5 -> 0 | AI28: INFONAVIT | AJ28: =+AJ5+AY5 -> 0 | AL28: INFONAVIT | AM28: =+AM5 -> 0 | AO28: INFONAVIT | AP28: =+AP5 -> 0 | AR28: INFONAVIT | AS28: =+AS5+AV5 -> 0 | BA28: INFONAVIT | BB28: =+BB5 -> 0 | BD28: INFONAVIT | BE28: =+BE5 -> 0 | BG28: INFONAVIT | BH28: =+BH5 -> 0
AF29: SAR | AG29: =+AG6 -> 0 | AI29: SAR | AJ29: =+AJ6+AY6 -> 0 | AL29: SAR | AM29: =+AM6 -> 0 | AO29: SAR | AP29: =+AP6 -> 0 | AR29: SAR | AS29: =+AS6+AV6 -> 0 | AU29: CHECAR CUADRO DE FORESTAL | AX29: CHECAR CUADRO DE CASCO II | BA29: SAR | BB29: =+BB6 -> 0 | BD29: SAR | BE29: =+BE6 -> 0 | BG29: SAR | BH29: =+BH6 -> 0
AF30: CESANTIA OBRERO | AG30: =+AG8 -> 0 | AI30: CESANTIA OBRERO | AJ30: =+AJ8+AY8 -> 0 | AL30: CESANTIA OBRERO | AM30: =+AM8 -> 0 | AO30: CESANTIA OBRERO | AP30: =+AP8 -> 0 | AR30: CESANTIA OBRERO | AS30: =+AS8+AV8 -> 0 | BA30: CESANTIA OBRERO | BB30: =+BB8 -> 0 | BD30: CESANTIA OBRERO | BE30: =+BE8 -> 0 | BG30: CESANTIA OBRERO | BH30: =+BH8 -> 0
AF31: IMSS OBRERO | AG31: =+AG10 -> 0 | AI31: IMSS OBRERO | AJ31: =+AJ10+AY10 -> 0 | AL31: IMSS OBRERO | AM31: =+AM10 -> 0 | AO31: IMSS OBRERO | AP31: =+AP10 -> 0 | AR31: IMSS OBRERO | AS31: =+AS10+AV10 -> 0 | BA31: IMSS OBRERO | BB31: =+BB10 -> 0 | BD31: IMSS OBRERO | BE31: =+BE10 -> 0 | BG31: IMSS OBRERO | BH31: =+BH10 -> 0
AF32: PATRONAL | AG32: =+AG9+AG7 -> 0 | AI32: PATRONAL | AJ32: =+AJ7+AJ9+AY7+AY9 -> 0 | AL32: PATRONAL | AM32: =+AM7+AM9 -> -4216.64 | AO32: PATRONAL | AP32: =+AP7+AP9 -> 0 | AR32: PATRONAL | AS32: =+AS7+AS9+AV7+AV9 -> 0 | BA32: PATRONAL | BB32: =+BB7+BB9 -> 0 | BD32: PATRONAL | BE32: =+BE7+BE9 -> 0 | BG32: PATRONAL | BH32: =+BH7+BH9 -> 0
AF33: SUMA | AG33: =SUM(AG28:AG32) -> 0 | AI33: SUMA | AJ33: =SUM(AJ28:AJ32) -> 0 | AL33: SUMA | AM33: =SUM(AM28:AM32) -> -4216.64 | AO33: SUMA | AP33: =SUM(AP28:AP32) -> 0 | AR33: SUMA | AS33: =SUM(AS28:AS32) -> 0 | BA33: SUMA | BB33: =SUM(BB28:BB32) -> 0 | BD33: SUMA | BE33: =SUM(BE28:BE32) -> 0 | BG33: SUMA | BH33: =SUM(BH28:BH32) -> 0
AF34: DIFERENCIA | AG34: =+AG11-AG33 -> 0 | AI34: DIFERENCIA | AJ34: =+AJ11+AY11-AJ33 -> 0 | AL34: DIFERENCIA | AM34: =+AM11-AM33 -> 0 | AO34: DIFERENCIA | AP34: =+AP11-AP33 -> 0 | AR34: DIFERENCIA | AS34: =+AS11+AV11-AS33 -> 0 | BA34: DIFERENCIA | BB34: =+BB11-BB33 -> 0 | BD34: DIFERENCIA | BE34: =+BE11-BE33 -> 0 | BG34: DIFERENCIA | BH34: =+BH11-BH33 -> 0
AF36: COMPROBACIÓN GENERAL
AF37: INFONAVIT | AG37: =+AG28+AJ28+AM28+AP28+AS28+BB28+BE28+BH28 -> 0
AF38: SAR | AG38: =+AG29+AJ29+AM29+AP29+AS29+BB29+BE29+BH29 -> 0
AF39: CESANTIA OBRERO | AG39: =+AG30+AJ30+AM30+AP30+AS30+BB30+BE30+BH30 -> 0
AF40: IMSS OBRERO | AG40: =+AG31+AJ31+AM31+AP31+AS31+BB31+BE31+BH31 -> 0
AF41: PATRONAL | AG41: =+AG32+AJ32+AM32+AP32+AS32+BB32+BE32+BH32 -> -4216.64
AF42: SUMA | AG42: =+AG33+AJ33+AM33+AP33+AS33+BB33+BE33+BH33 -> -4216.64
AF43: DIFERENCIA | AG43: =+AG34+AJ34+AM34+AP34+AS34+BB34+BE34+BH34 -> 0
I53: =SUM(I29:I52) -> 0 | J53: =SUM(J29:J52) -> 0 | K53: =SUM(K29:K52) -> 0 | L53: =SUM(L29:L52) -> 0 | M53: =SUM(M29:M52) -> 0 | N53: =SUM(N29:N52) -> 0 | O53: =SUM(O29:O52) -> 0 | P53: =SUM(P29:P52) -> 0 | ... AD53: =SUM(AD29:AD52) -> 0 | AF53: DIFERENCIA | AG53: =+AG33-AG11 -> 0
B55: =+C56 -> 0
I79: =SUM(I56:I78) -> 0 | J79: =SUM(J56:J78) -> 0 | K79: =SUM(K56:K78) -> 0 | L79: =SUM(L56:L78) -> 0 | M79: =SUM(M56:M78) -> 0 | N79: =SUM(N56:N78) -> 0 | O79: =SUM(O56:O78) -> 0 | P79: =SUM(P56:P78) -> 0 | ... AD79: =SUM(AD56:AD78) -> 0
...

Sheet Hoja4
B2: ACIENTO CONTABLE
L3: IMSS | M3: 403856.08 | N3: =+F4+F11+F18+F25+F32+F39+F46+F53 -> -4216.64
B4: ADMINISTRACION | C4: 5200-10-001-021 | D4: IMSS Patronal | F4: =+FEBRERO!$AG$9 -> 0 | L4: Infonavit | M4: =376291.94-2356.34 -> 373935.6 | N4: =+F5+F12+F19+F26+F33+F40+F47+F54 -> 14096.07
C5: 5200-10-001-023 | D5: Infonavit | F5: =+FEBRERO!$AG$5+2181.36 -> 2181.36 | L5: Afore | M5: 149494.25 | N5: =+F6+F13+F20+F27+F34+F41+F48+F55 -> 17449.52
C6: 5200-10-001-022 | D6: Afore | F6: =+FEBRERO!$AG$6+2181.36 -> 2181.36 | L6: Cesantia y vejez | M6: 457921.61 | N6: =+F7+F14+F21+F28+F35+F42+F49+F56 -> 18450.88
C7: 5200-10-001-025 | D7: Cesantia y vejez | F7: =+FEBRERO!$AG$7+2181.36 -> 2181.36 | M7: =SUM(M3:M6) -> 1385207.5 | N7: =SUM(N3:N6) -> 45779.83
C8: 2104-04-001-002 | D8: IMSS PATRONAL | G8: 29197.57 | M8: 87923.38
C9: 2104-04-002-002 | D9: INFONAVIT | G9: =+F5 -> 2181.36 | M9: =+M7+M8 -> 1473130.9
C10: 2104-04-002-001 | D10: RETIRO, CESANTIA Y VEJEZ | G10: =+F6+F7 -> 4362.72 | M10: =+M9-F62 -> 1477347.6 | O10: =1473130.92-87923.38 -> 1385207.5
B11: OPERACIÓN Y CASCO II | C11: 5200-10-002-021 | D11: IMSS Patronal | F11: =+FEBRERO!$AJ$9+FEBRERO!$AY$9 -> 0 | M11: =+M7+M10 -> 2862555.1 | O11: =+M7-O10 -> 0
C12: 5200-10-002-023 | D12: Infonavit | F12: =+FEBRERO!$AJ$5+FEBRERO!$AY$5+2000-2356.34 -> -356.34
C13: 5200-10-002-022 | D13: Afore | F13: =+FEBRERO!$AJ$6+FEBRERO!$AY$6+2181.36 -> 2181.36
C14: 5200-10-002-025 | D14: Cesantia y vejez | F14: =+FEBRERO!$AJ$7+FEBRERO!$AY$7+2181.36 -> 2181.36
C15: 2104-04-001-002 | D15: IMSS PATRONAL | G15: =+F11 -> 0
C16: 2104-04-002-002 | D16: INFONAVIT | G16: =+F12 -> -356.34
C17: 2104-04-002-001 | D17: RETIRO, CESANTIA Y VEJEZ | G17: =+F13+F14 -> 4362.72
B18: PRODUCCION | C18: 5200-10-003-021 | D18: IMSS Patronal | F18: =+FEBRERO!$BB$9 -> 0
C19: 5200-10-003-023 | D19: Infonavit | F19: =+FEBRERO!$BB$5+2000 -> 2000
C20: 5200-10-003-022 | D20: Afore | F20: =+FEBRERO!$BB$6+2181.36 -> 2181.36
C21: 5200-10-003-025 | D21: Cesantia y vejez | F21: =+FEBRERO!$BB$7+2181.36 -> 2181.36
C22: 2104-04-001-002 | D22: IMSS PATRONAL | G22: =+F18 -> 0
C23: 2104-04-002-002 | D23: INFONAVIT | G23: =+F19 -> 2000
C24: 2104-04-002-001 | D24: RETIRO, CESANTIA Y VEJEZ | G24: =+F20+F21 -> 4362.72
B25: TRANING | C25: 5200-40-001-013 | D25: IMSS Patronal | F25: =+FEBRERO!$BH$9 -> 0
C26: 5200-40-001-015 | D26: Infonavit | F26: =+FEBRERO!$BH$5+2000 -> 2000
C27: 5200-40-001-014 | D27: Afore | F27: =+FEBRERO!$BH$6+2181.36 -> 2181.36
C28: 5200-40-001-025 | D28: Cesantia y vejez | F28: =+FEBRERO!$BH$7+3181.36 -> 3181.36
C29: 2104-04-001-002 | D29: IMSS PATRONAL | G29: =+F25 -> 0
C30: 2104-04-002-002 | D30: INFONAVIT | G30: =+F26 -> 2000
C31: 2104-04-002-001 | D31: RETIRO, CESANTIA Y VEJEZ | G31: =+F27+F28 -> 5362.72
B32: CORRALES | C32: 5200-30-001-013 | D32: IMSS Patronal | F32: =+FEBRERO!$AP$9 -> 0
C33: 5200-30-001-015 | D33: Infonavit | F33: =+FEBRERO!$AP$5+2000 -> 2000
C34: 5200-30-001-014 | D34: Afore | F34: =+FEBRERO!$AP$6+2181.36 -> 2181.36
C35: 5200-30-001-025 | D35: Cesantia y vejez | F35: =+FEBRERO!$AP$7+2181.36 -> 2181.36
C36: 2104-04-001-002 | D36: IMSS PATRONAL | G36: =+F32 -> 0
C37: 2104-04-002-002 | D37: INFONAVIT | G37: =+F33 -> 2000
C38: 2104-04-002-001 | D38: RETIRO, CESANTIA Y VEJEZ | G38: =+F34+F35 -> 4362.72
B39: JARDINES Y FORESTAL | C39: 5200-10-003-021 | D39: IMSS Patronal | F39: =+FEBRERO!$AS$9+FEBRERO!$AV$9 -> 0
C40: 5200-10-003-023 | D40: Infonavit | F40: =+FEBRERO!$AS$5+FEBRERO!$AV$5+2000 -> 2000
C41: 5200-10-003-022 | D41: Afore | F41: =+FEBRERO!$AS$6+FEBRERO!$AV$6+2181.36 -> 2181.36
...
